<robot name="jijin_wheel_robot">

  #define a base_link on the ground
  <link name="base_link"/>

  #add a robot body
  <link name="body_link">
    <visual>
      <geometry>
        <box size="0.5 0.5 0.35"/>
      </geometry>
      <origin xyz="0 0 0" rpy="0 0 0"/>
    </visual>
    <collision>
      <geometry>
        <box size="0.5 0.5 0.35"/>
      </geometry>
      <origin xyz="0 0 0" rpy="0 0 0"/>
    </collision>
    <inertial>
       <origin xyz="0 0 0" rpy="0 0 0"/>
       <mass value="5"/>
       <inertia ixx="1"  ixy="0"  ixz="0" iyy="1" iyz="0" izz="1" />
    </inertial>
  </link>
  <joint name="body_joint" type="fixed">
    <parent link="base_link"/>
    <child  link="body_link"/>
    <origin xyz="0 0 0.2" rpy="0 0 0" />
  </joint>

  #add left wheels
  <link name="wheel_left">
    <visual>
      <geometry>
        <cylinder radius="0.2" length="0.1"/>
      </geometry>
      <origin xyz="0 0 0" rpy="1.57 0 0"/>
    </visual>
    <collision>
      <geometry>
        <cylinder radius="0.2" length="0.1"/>
      </geometry>
      <origin xyz="0 0 0" rpy="1.57 0 0"/>
    </collision>
    <inertial>
       <origin xyz="0 0 0" rpy="1.57 0 0"/>
       <mass value="1"/>
       <inertia ixx="1"  ixy="0"  ixz="0" iyy="1" iyz="0" izz="1" />
    </inertial>
  </link>
  <joint name="wheel_left_joint" type="continuous">
    <parent link="body_link"/>
    <child  link="wheel_left"/>
    <origin xyz="0 0.3 0" rpy="0 0 0" />
    <axis xyz="0 1 0"/>
    <limit effort="100" velocity="100"/>
    <joint_properties damping="0.0" friction="0.0"/>
  </joint>


  #add right wheels
  <link name="wheel_right">
    <visual>
      <geometry>
        <cylinder radius="0.2" length="0.1"/>
      </geometry>
      <origin xyz="0 0 0" rpy="1.57 0 0"/>
    </visual>
    <collision>
      <geometry>
        <cylinder radius="0.2" length="0.1"/>
      </geometry>
      <origin xyz="0 0 0" rpy="1.57 0 0"/>
    </collision>
    <inertial>
       <origin xyz="0 0 0" rpy="1.57 0 0"/>
       <mass value="1"/>
       <inertia ixx="1"  ixy="0"  ixz="0" iyy="1" iyz="0" izz="1" />
    </inertial>
  </link>
  <joint name="wheel_right_joint" type="continuous">
    <parent link="body_link"/>
    <child  link="wheel_right"/>
    <origin xyz="0 -0.3 0" rpy="0 0 0" />
    <axis xyz="0 1 0"/>
    <limit effort="100" velocity="100"/>
    <joint_properties damping="0.0" friction="0.0"/>
  </joint>

</robot>

