<robot name="jijin_gripper" xmlns:xacro="http://ros.org/wiki/xacro">

  <xacro:macro name="jijin_gripper" params="parent_link *joint_pose">
    #define a base_link of gripper
    <link name="gripper_base_link">
      <visual>
        <geometry>
          <box size="0.1 0.2 0.1"/>
        </geometry>
        <origin xyz="0 0 0.05" rpy="0 0 0"/>
      </visual>
      <collision>
        <geometry>
          <box size="0.1 0.2 0.1"/>
        </geometry>
        <origin xyz="0 0 0.05" rpy="0 0 0"/>
      </collision>
      <inertial>
         <origin xyz="0 0 0.05" rpy="0 0 0"/>
         <mass value="0.1"/>
         <inertia ixx="1"  ixy="0"  ixz="0" iyy="1" iyz="0" izz="1" />
      </inertial>
    </link>
    <joint name="gripper_base_link_joint" type="fixed">
      <parent link="${parent_link}"/>
      <child  link="gripper_base_link"/>
      <xacro:insert_block name="joint_pose"/>
    </joint>


    # left finger
    <link name="finger_left_link">
      <visual>
        <geometry>
          <box size="0.1 0.01 0.1"/>
        </geometry>
        <origin xyz="0 0 0.05" rpy="0 0 0"/>
      </visual>
      <collision>
        <geometry>
          <box size="0.1 0.01 0.1"/>
        </geometry>
        <origin xyz="0 0 0.05" rpy="0 0 0"/>
      </collision>
      <inertial>
         <origin xyz="0 0 0.05" rpy="0 0 0"/>
         <mass value="0.1"/>
         <inertia ixx="1"  ixy="0"  ixz="0" iyy="1" iyz="0" izz="1" />
      </inertial>
    </link>
    <joint name="finger_left_joint" type="prismatic">
      <parent link="gripper_base_link"/>
      <child  link="finger_left_link"/>
      <origin xyz="0 0.1 0.1" rpy="0 0 0" />
      <axis xyz="0 1 0"/>
      <limit lower="-0.09" upper="0" effort="100" velocity="100"/>
      <joint_properties damping="0.0" friction="0.0"/>
    </joint>

    # right finger
    <link name="finger_right_link">
      <visual>
        <geometry>
          <box size="0.1 0.01 0.1"/>
        </geometry>
        <origin xyz="0 0 0.05" rpy="0 0 0"/>
      </visual>
      <collision>
        <geometry>
          <box size="0.1 0.01 0.1"/>
        </geometry>
        <origin xyz="0 0 0.05" rpy="0 0 0"/>
      </collision>
      <inertial>
         <origin xyz="0 0 0.05" rpy="0 0 0"/>
         <mass value="0.1"/>
         <inertia ixx="1"  ixy="0"  ixz="0" iyy="1" iyz="0" izz="1" />
      </inertial>
    </link>
    <joint name="finger_right_joint" type="prismatic">
      <parent link="gripper_base_link"/>
      <child  link="finger_right_link"/>
      <origin xyz="0 -0.1 0.1" rpy="0 0 0" />
      <axis xyz="0 1 0"/>
      <limit lower="0" upper="0.09" effort="100" velocity="100"/>
      <joint_properties damping="0.0" friction="0.0"/>
    </joint>

  </xacro:macro>
</robot>

